[2024-05-05T15:59:31.155+0000] {local_task_job_runner.py:120} INFO - ::group::Pre task execution logs
[2024-05-05T15:59:31.541+0000] {taskinstance.py:2073} INFO - Dependencies all met for dep_context=non-requeueable deps ti=<TaskInstance: etl.create_tables scheduled__2024-04-13T00:00:00+00:00 [queued]>
[2024-05-05T15:59:31.662+0000] {taskinstance.py:2073} INFO - Dependencies all met for dep_context=requeueable deps ti=<TaskInstance: etl.create_tables scheduled__2024-04-13T00:00:00+00:00 [queued]>
[2024-05-05T15:59:31.680+0000] {taskinstance.py:2303} INFO - Starting attempt 1 of 1
[2024-05-05T15:59:31.868+0000] {taskinstance.py:2327} INFO - Executing <Task(PythonOperator): create_tables> on 2024-04-13 00:00:00+00:00
[2024-05-05T15:59:32.124+0000] {warnings.py:110} WARNING - /home/***/.local/lib/python3.12/site-packages/***/task/task_runner/standard_task_runner.py:61: DeprecationWarning: This process (pid=535) is multi-threaded, use of fork() may lead to deadlocks in the child.
  pid = os.fork()

[2024-05-05T15:59:32.125+0000] {standard_task_runner.py:63} INFO - Started process 577 to run task
[2024-05-05T15:59:32.075+0000] {standard_task_runner.py:90} INFO - Running: ['***', 'tasks', 'run', 'etl', 'create_tables', 'scheduled__2024-04-13T00:00:00+00:00', '--job-id', '51', '--raw', '--subdir', 'DAGS_FOLDER/etl.py', '--cfg-path', '/tmp/tmpxu9dy2pi']
[2024-05-05T15:59:32.161+0000] {standard_task_runner.py:91} INFO - Job 51: Subtask create_tables
[2024-05-05T15:59:32.562+0000] {task_command.py:426} INFO - Running <TaskInstance: etl.create_tables scheduled__2024-04-13T00:00:00+00:00 [running]> on host edcd6c8e3dad
[2024-05-05T15:59:33.360+0000] {taskinstance.py:2644} INFO - Exporting env vars: AIRFLOW_CTX_DAG_OWNER='***' AIRFLOW_CTX_DAG_ID='etl' AIRFLOW_CTX_TASK_ID='create_tables' AIRFLOW_CTX_EXECUTION_DATE='2024-04-13T00:00:00+00:00' AIRFLOW_CTX_TRY_NUMBER='1' AIRFLOW_CTX_DAG_RUN_ID='scheduled__2024-04-13T00:00:00+00:00'
[2024-05-05T15:59:33.385+0000] {taskinstance.py:430} INFO - ::endgroup::
[2024-05-05T15:59:33.485+0000] {taskinstance.py:441} INFO - ::group::Post task execution logs
[2024-05-05T15:59:33.601+0000] {taskinstance.py:2890} ERROR - Task failed with exception
Traceback (most recent call last):
  File "/home/airflow/.local/lib/python3.12/site-packages/airflow/models/taskinstance.py", line 465, in _execute_task
    result = _execute_callable(context=context, **execute_callable_kwargs)
             ^^^^^^^^^^^^^^^^^^^^^^^^^^^^^^^^^^^^^^^^^^^^^^^^^^^^^^^^^^^^^
  File "/home/airflow/.local/lib/python3.12/site-packages/airflow/models/taskinstance.py", line 432, in _execute_callable
    return execute_callable(context=context, **execute_callable_kwargs)
           ^^^^^^^^^^^^^^^^^^^^^^^^^^^^^^^^^^^^^^^^^^^^^^^^^^^^^^^^^^^^
  File "/home/airflow/.local/lib/python3.12/site-packages/airflow/models/baseoperator.py", line 400, in wrapper
    return func(self, *args, **kwargs)
           ^^^^^^^^^^^^^^^^^^^^^^^^^^^
  File "/home/airflow/.local/lib/python3.12/site-packages/airflow/operators/python.py", line 235, in execute
    return_value = self.execute_callable()
                   ^^^^^^^^^^^^^^^^^^^^^^^
  File "/home/airflow/.local/lib/python3.12/site-packages/airflow/operators/python.py", line 252, in execute_callable
    return self.python_callable(*self.op_args, **self.op_kwargs)
           ^^^^^^^^^^^^^^^^^^^^^^^^^^^^^^^^^^^^^^^^^^^^^^^^^^^^^
  File "/opt/airflow/dags/etl.py", line 52, in _create_table
    conn = hook.get_conn()
           ^^^^^^^^^^^^^^^
  File "/home/airflow/.local/lib/python3.12/site-packages/airflow/providers/postgres/hooks/postgres.py", line 131, in get_conn
    conn = deepcopy(self.connection or self.get_connection(conn_id))
                                       ^^^^^^^^^^^^^^^^^^^^^^^^^^^^
  File "/home/airflow/.local/lib/python3.12/site-packages/airflow/hooks/base.py", line 83, in get_connection
    conn = Connection.get_connection_from_secrets(conn_id)
           ^^^^^^^^^^^^^^^^^^^^^^^^^^^^^^^^^^^^^^^^^^^^^^^
  File "/home/airflow/.local/lib/python3.12/site-packages/airflow/models/connection.py", line 519, in get_connection_from_secrets
    raise AirflowNotFoundException(f"The conn_id `{conn_id}` isn't defined")
airflow.exceptions.AirflowNotFoundException: The conn_id `my_postgres_conn` isn't defined
[2024-05-05T15:59:33.700+0000] {taskinstance.py:1205} INFO - Marking task as FAILED. dag_id=etl, task_id=create_tables, execution_date=20240413T000000, start_date=20240505T155931, end_date=20240505T155933
[2024-05-05T15:59:34.001+0000] {standard_task_runner.py:110} ERROR - Failed to execute job 51 for task create_tables (The conn_id `my_postgres_conn` isn't defined; 577)
[2024-05-05T15:59:34.243+0000] {local_task_job_runner.py:240} INFO - Task exited with return code 1
[2024-05-05T15:59:34.726+0000] {taskinstance.py:3482} INFO - 0 downstream tasks scheduled from follow-on schedule check
[2024-05-05T15:59:34.782+0000] {local_task_job_runner.py:222} INFO - ::endgroup::
